<robot name = "robot">
    <link name="Link0">
        <inertial>
            <origin xyz="0 0 0.44534623721731825" rpy="0 0 0"/>
            <mass value="1" />
            <inertia ixx="100" ixy="0" ixz="0" iyy="100" iyz="0" izz="100" />
        </inertial>
        <visual>
            <origin xyz="0 0 0.44534623721731825" rpy="0 0 0"/>
            <geometry>
                <box size="0.3872675945979489 0.7930130119237252 0.3219849786517617" />
            </geometry>
            <material name="Cyan">
                <color rgba="0 1.0 1.0 1.0"/>
            </material>
        </visual>
        <collision>
            <origin xyz="0 0 0.44534623721731825" rpy="0 0 0"/>
            <geometry>
                <box size="0.3872675945979489 0.7930130119237252 0.3219849786517617" />
            </geometry>
        </collision>
    </link>
    <joint name="Link0_Link3" type="revolute">
       <parent link="Link0"/>
       <child  link="Link3"/>
       <origin rpy="0 0 0" xyz="0.19363379729897445 0.29686132986118746 0.4650718227462075" />
     <axis xyz="0 1 0"/>
       <limit effort="0.0" lower="-3.14159" upper="3.14159" velocity="0.0"/>
    </joint>
    <joint name="Link0_Link1" type="revolute">
       <parent link="Link0"/>
       <child  link="Link1"/>
       <origin rpy="0 0 0" xyz="-0.19363379729897445 0.08095829896465795 0.5146197290351409" />
     <axis xyz="1 0 0"/>
       <limit effort="0.0" lower="-3.14159" upper="3.14159" velocity="0.0"/>
    </joint>
    <joint name="Link0_Link2" type="revolute">
       <parent link="Link0"/>
       <child  link="Link2"/>
       <origin rpy="0 0 0" xyz="-0.1452738487759643 0.3965065059618626 0.4515190972661096" />
     <axis xyz="0 1 0"/>
       <limit effort="0.0" lower="-3.14159" upper="3.14159" velocity="0.0"/>
    </joint>
    <joint name="Link0_Link4" type="revolute">
       <parent link="Link0"/>
       <child  link="Link4"/>
       <origin rpy="0 0 0" xyz="-0.06797560536202223 0.23931295272657804 0.6063387265431991" />
     <axis xyz="1 0 0"/>
       <limit effort="0.0" lower="-3.14159" upper="3.14159" velocity="0.0"/>
    </joint>
    <link name="Link1">
        <inertial>
            <origin xyz="-0.46487164725660424 0 0" rpy="0 0 0"/>
            <mass value="1" />
            <inertia ixx="100" ixy="0" ixz="0" iyy="100" iyz="0" izz="100" />
        </inertial>
        <visual>
            <origin xyz="-0.46487164725660424 0 0" rpy="0 0 0"/>
            <geometry>
                <box size="0.9297432945132085 0.049076668974213145 0.3487241274256687" />
            </geometry>
            <material name="Green">
                <color rgba="0 1.0 0 1.0"/>
            </material>
        </visual>
        <collision>
            <origin xyz="-0.46487164725660424 0 0" rpy="0 0 0"/>
            <geometry>
                <box size="0.9297432945132085 0.049076668974213145 0.3487241274256687" />
            </geometry>
        </collision>
    </link>
    <link name="Link2">
        <inertial>
            <origin xyz="0 0.20142952134297437 0" rpy="0 0 0"/>
            <mass value="1" />
            <inertia ixx="100" ixy="0" ixz="0" iyy="100" iyz="0" izz="100" />
        </inertial>
        <visual>
            <origin xyz="0 0.20142952134297437 0" rpy="0 0 0"/>
            <geometry>
                <box size="0.643233346092724 0.40285904268594874 0.027054731037775448" />
            </geometry>
            <material name="Cyan">
                <color rgba="0 1.0 1.0 1.0"/>
            </material>
        </visual>
        <collision>
            <origin xyz="0 0.20142952134297437 0" rpy="0 0 0"/>
            <geometry>
                <box size="0.643233346092724 0.40285904268594874 0.027054731037775448" />
            </geometry>
        </collision>
    </link>
    <link name="Link3">
        <inertial>
            <origin xyz="0.11570670723869175 0 0" rpy="0 0 0"/>
            <mass value="1" />
            <inertia ixx="100" ixy="0" ixz="0" iyy="100" iyz="0" izz="100" />
        </inertial>
        <visual>
            <origin xyz="0.11570670723869175 0 0" rpy="0 0 0"/>
            <geometry>
                <box size="0.2314134144773835 0.03212634234273026 0.41801029439377835" />
            </geometry>
            <material name="Cyan">
                <color rgba="0 1.0 1.0 1.0"/>
            </material>
        </visual>
        <collision>
            <origin xyz="0.11570670723869175 0 0" rpy="0 0 0"/>
            <geometry>
                <box size="0.2314134144773835 0.03212634234273026 0.41801029439377835" />
            </geometry>
        </collision>
    </link>
    <link name="Link4">
        <inertial>
            <origin xyz="0 0 0.034353747891437414" rpy="0 0 0"/>
            <mass value="1" />
            <inertia ixx="100" ixy="0" ixz="0" iyy="100" iyz="0" izz="100" />
        </inertial>
        <visual>
            <origin xyz="0 0 0.034353747891437414" rpy="0 0 0"/>
            <geometry>
                <box size="0.167759182808203 0.2506867943689979 0.06870749578287483" />
            </geometry>
            <material name="Cyan">
                <color rgba="0 1.0 1.0 1.0"/>
            </material>
        </visual>
        <collision>
            <origin xyz="0 0 0.034353747891437414" rpy="0 0 0"/>
            <geometry>
                <box size="0.167759182808203 0.2506867943689979 0.06870749578287483" />
            </geometry>
        </collision>
    </link>
</robot>