<robot name = "robot">
    <link name="Link0">
        <inertial>
            <origin xyz="0 0 1.25" rpy="0 0 0"/>
            <mass value="1" />
            <inertia ixx="100" ixy="0" ixz="0" iyy="100" iyz="0" izz="100" />
        </inertial>
        <visual>
            <origin xyz="0 0 1.25" rpy="0 0 0"/>
            <geometry>
                <box size="0.0954939078170296 0.7704554839698069 0.8982480578970979" />
            </geometry>
            <material name="Green">
                <color rgba="0 1.0 0 1.0"/>
            </material>
        </visual>
        <collision>
            <origin xyz="0 0 1.25" rpy="0 0 0"/>
            <geometry>
                <box size="0.0954939078170296 0.7704554839698069 0.8982480578970979" />
            </geometry>
        </collision>
    </link>
    <joint name="Link0_Link1" type="revolute">
       <parent link="Link0"/>
       <child  link="Link1"/>
       <origin rpy="0 0 0" xyz="-0.0477469539085148 -0.008458950671730166 1.2301600457472057" />
     <axis xyz="0 0 1"/>
       <limit effort="0.0" lower="-3.14159" upper="3.14159" velocity="0.0"/>
    </joint>
    <joint name="Link0_Link2" type="revolute">
       <parent link="Link0"/>
       <child  link="Link2"/>
       <origin rpy="0 0 0" xyz="0.0303208221935204 0.07150670119279515 1.699124028948549" />
     <axis xyz="0 1 0"/>
       <limit effort="0.0" lower="-3.14159" upper="3.14159" velocity="0.0"/>
    </joint>
    <link name="Link1">
        <inertial>
            <origin xyz="-0.2346197700471893 0 0" rpy="0 0 0"/>
            <mass value="1" />
            <inertia ixx="100" ixy="0" ixz="0" iyy="100" iyz="0" izz="100" />
        </inertial>
        <visual>
            <origin xyz="-0.2346197700471893 0 0" rpy="0 0 0"/>
            <geometry>
                <box size="0.4692395400943786 0.6057270869259413 0.134824434364485" />
            </geometry>
            <material name="Green">
                <color rgba="0 1.0 0 1.0"/>
            </material>
        </visual>
        <collision>
            <origin xyz="-0.2346197700471893 0 0" rpy="0 0 0"/>
            <geometry>
                <box size="0.4692395400943786 0.6057270869259413 0.134824434364485" />
            </geometry>
        </collision>
    </link>
    <link name="Link2">
        <inertial>
            <origin xyz="0 0 0.27288248170562984" rpy="0 0 0"/>
            <mass value="1" />
            <inertia ixx="100" ixy="0" ixz="0" iyy="100" iyz="0" izz="100" />
        </inertial>
        <visual>
            <origin xyz="0 0 0.27288248170562984" rpy="0 0 0"/>
            <geometry>
                <box size="0.06747046464012663 0.5779467538180059 0.5457649634112597" />
            </geometry>
            <material name="Cyan">
                <color rgba="0 1.0 1.0 1.0"/>
            </material>
        </visual>
        <collision>
            <origin xyz="0 0 0.27288248170562984" rpy="0 0 0"/>
            <geometry>
                <box size="0.06747046464012663 0.5779467538180059 0.5457649634112597" />
            </geometry>
        </collision>
    </link>
</robot>