<robot name = "robot">
    <link name="Link0">
        <inertial>
            <origin xyz="0 0 3.75" rpy="0 0 0"/>
            <mass value="1" />
            <inertia ixx="100" ixy="0" ixz="0" iyy="100" iyz="0" izz="100" />
        </inertial>
        <visual>
            <origin xyz="0 0 3.75" rpy="0 0 0"/>
            <geometry>
                <box size="0.6366761185099019 0.8470632469629397 0.5808757702975704" />
            </geometry>
            <material name="Cyan">
                <color rgba="0 1.0 1.0 1.0"/>
            </material>
        </visual>
        <collision>
            <origin xyz="0 0 3.75" rpy="0 0 0"/>
            <geometry>
                <box size="0.6366761185099019 0.8470632469629397 0.5808757702975704" />
            </geometry>
        </collision>
    </link>
    <joint name="Link0_Link1" type="revolute">
       <parent link="Link0"/>
       <child  link="Link1"/>
       <origin rpy="0 0 0" xyz="-0.31833805925495096 -0.014969161105980212 3.9068895362026055" />
     <axis xyz="0 1 0"/>
       <limit effort="0.0" lower="-3.14159" upper="3.14159" velocity="0.0"/>
    </joint>
    <joint name="Link0_Link4" type="revolute">
       <parent link="Link0"/>
       <child  link="Link4"/>
       <origin rpy="0 0 0" xyz="-0.3135902585560861 0.42353162348146983 3.5371990030847997" />
     <axis xyz="0 0 1"/>
       <limit effort="0.0" lower="-3.14159" upper="3.14159" velocity="0.0"/>
    </joint>
    <joint name="Link0_Link2" type="revolute">
       <parent link="Link0"/>
       <child  link="Link2"/>
       <origin rpy="0 0 0" xyz="-0.14561946665789613 -0.39494458023953743 4.040437885148785" />
     <axis xyz="0 1 0"/>
       <limit effort="0.0" lower="-3.14159" upper="3.14159" velocity="0.0"/>
    </joint>
    <link name="Link1">
        <inertial>
            <origin xyz="-0.4151759866528388 0 0" rpy="0 0 0"/>
            <mass value="1" />
            <inertia ixx="100" ixy="0" ixz="0" iyy="100" iyz="0" izz="100" />
        </inertial>
        <visual>
            <origin xyz="-0.4151759866528388 0 0" rpy="0 0 0"/>
            <geometry>
                <box size="0.8303519733056776 0.346788662213973 0.5497700837294708" />
            </geometry>
            <material name="Green">
                <color rgba="0 1.0 0 1.0"/>
            </material>
        </visual>
        <collision>
            <origin xyz="-0.4151759866528388 0 0" rpy="0 0 0"/>
            <geometry>
                <box size="0.8303519733056776 0.346788662213973 0.5497700837294708" />
            </geometry>
        </collision>
    </link>
    <joint name="Link1_Link3" type="revolute">
       <parent link="Link1"/>
       <child  link="Link3"/>
       <origin rpy="0 0 0" xyz="-0.8303519733056776 -0.06801208435963421 -0.18820941573883412" />
     <axis xyz="1 0 0"/>
       <limit effort="0.0" lower="-3.14159" upper="3.14159" velocity="0.0"/>
    </joint>
    <link name="Link2">
        <inertial>
            <origin xyz="0 0 0.11296546823765019" rpy="0 0 0"/>
            <mass value="1" />
            <inertia ixx="100" ixy="0" ixz="0" iyy="100" iyz="0" izz="100" />
        </inertial>
        <visual>
            <origin xyz="0 0 0.11296546823765019" rpy="0 0 0"/>
            <geometry>
                <box size="0.5735804490308563 0.7626302250150341 0.22593093647530038" />
            </geometry>
            <material name="Green">
                <color rgba="0 1.0 0 1.0"/>
            </material>
        </visual>
        <collision>
            <origin xyz="0 0 0.11296546823765019" rpy="0 0 0"/>
            <geometry>
                <box size="0.5735804490308563 0.7626302250150341 0.22593093647530038" />
            </geometry>
        </collision>
    </link>
    <link name="Link3">
        <inertial>
            <origin xyz="-0.0815595877399149 0 0" rpy="0 0 0"/>
            <mass value="1" />
            <inertia ixx="100" ixy="0" ixz="0" iyy="100" iyz="0" izz="100" />
        </inertial>
        <visual>
            <origin xyz="-0.0815595877399149 0 0" rpy="0 0 0"/>
            <geometry>
                <box size="0.1631191754798298 0.5723275364575965 0.4093042471073296" />
            </geometry>
            <material name="Green">
                <color rgba="0 1.0 0 1.0"/>
            </material>
        </visual>
        <collision>
            <origin xyz="-0.0815595877399149 0 0" rpy="0 0 0"/>
            <geometry>
                <box size="0.1631191754798298 0.5723275364575965 0.4093042471073296" />
            </geometry>
        </collision>
    </link>
    <link name="Link4">
        <inertial>
            <origin xyz="0 0.4130397033111358 0" rpy="0 0 0"/>
            <mass value="1" />
            <inertia ixx="100" ixy="0" ixz="0" iyy="100" iyz="0" izz="100" />
        </inertial>
        <visual>
            <origin xyz="0 0.4130397033111358 0" rpy="0 0 0"/>
            <geometry>
                <box size="0.18034579604721634 0.8260794066222716 0.15241175403673834" />
            </geometry>
            <material name="Cyan">
                <color rgba="0 1.0 1.0 1.0"/>
            </material>
        </visual>
        <collision>
            <origin xyz="0 0.4130397033111358 0" rpy="0 0 0"/>
            <geometry>
                <box size="0.18034579604721634 0.8260794066222716 0.15241175403673834" />
            </geometry>
        </collision>
    </link>
</robot>