<robot name = "robot">
    <link name="Link0">
        <inertial>
            <origin xyz="0 0 1.25" rpy="0 0 0"/>
            <mass value="1" />
            <inertia ixx="100" ixy="0" ixz="0" iyy="100" iyz="0" izz="100" />
        </inertial>
        <visual>
            <origin xyz="0 0 1.25" rpy="0 0 0"/>
            <geometry>
                <box size="0.9227872430175995 0.9722018957879508 0.5142045234547575" />
            </geometry>
            <material name="Green">
                <color rgba="0 1.0 0 1.0"/>
            </material>
        </visual>
        <collision>
            <origin xyz="0 0 1.25" rpy="0 0 0"/>
            <geometry>
                <box size="0.9227872430175995 0.9722018957879508 0.5142045234547575" />
            </geometry>
        </collision>
    </link>
    <link name="Link1">
        <inertial>
            <origin xyz="-0.22936698768931446 0 0" rpy="0 0 0"/>
            <mass value="1" />
            <inertia ixx="100" ixy="0" ixz="0" iyy="100" iyz="0" izz="100" />
        </inertial>
        <visual>
            <origin xyz="-0.22936698768931446 0 0" rpy="0 0 0"/>
            <geometry>
                <box size="0.4587339753786289 0.8670154565723744 0.43959595966555276" />
            </geometry>
            <material name="Green">
                <color rgba="0 1.0 0 1.0"/>
            </material>
        </visual>
        <collision>
            <origin xyz="-0.22936698768931446 0 0" rpy="0 0 0"/>
            <geometry>
                <box size="0.4587339753786289 0.8670154565723744 0.43959595966555276" />
            </geometry>
        </collision>
    </link>
    <link name="Link2">
        <inertial>
            <origin xyz="0 0 -0.3725894331175371" rpy="0 0 0"/>
            <mass value="1" />
            <inertia ixx="100" ixy="0" ixz="0" iyy="100" iyz="0" izz="100" />
        </inertial>
        <visual>
            <origin xyz="0 0 -0.3725894331175371" rpy="0 0 0"/>
            <geometry>
                <box size="0.8024916772725246 0.23522205332370139 0.7451788662350742" />
            </geometry>
            <material name="Green">
                <color rgba="0 1.0 0 1.0"/>
            </material>
        </visual>
        <collision>
            <origin xyz="0 0 -0.3725894331175371" rpy="0 0 0"/>
            <geometry>
                <box size="0.8024916772725246 0.23522205332370139 0.7451788662350742" />
            </geometry>
        </collision>
    </link>
    <joint name="Link0_Link1" type="revolute">
       <parent link="Link0"/>
       <child  link="Link1"/>
       <origin rpy="0 0 0" xyz="-0.46139362150879976 -0.09028497875586888 1.241806833550556" />
     <axis xyz="1 0 0"/>
       <limit effort="0.0" lower="-3.14159" upper="3.14159" velocity="0.0"/>
    </joint>
    <joint name="Link0_Link2" type="revolute">
       <parent link="Link0"/>
       <child  link="Link2"/>
       <origin rpy="0 0 0" xyz="0.17917583252570254 -0.07292695484713008 0.9928977382726212" />
     <axis xyz="0 1 0"/>
       <limit effort="0.0" lower="-3.14159" upper="3.14159" velocity="0.0"/>
    </joint>
</robot>