<robot name = "robot">
    <link name="Link0">
        <inertial>
            <origin xyz="0 0 2.0" rpy="0 0 0"/>
            <mass value="1" />
            <inertia ixx="100" ixy="0" ixz="0" iyy="100" iyz="0" izz="100" />
        </inertial>
        <visual>
            <origin xyz="0 0 2.0" rpy="0 0 0"/>
            <geometry>
                <box size="0.8703178843561625 0.727076488475685 0.89456094910207" />
            </geometry>
            <material name="Cyan">
                <color rgba="0 1.0 1.0 1.0"/>
            </material>
        </visual>
        <collision>
            <origin xyz="0 0 2.0" rpy="0 0 0"/>
            <geometry>
                <box size="0.8703178843561625 0.727076488475685 0.89456094910207" />
            </geometry>
        </collision>
    </link>
    <link name="Link1">
        <inertial>
            <origin xyz="0 0 -0.49744406562410487" rpy="0 0 0"/>
            <mass value="1" />
            <inertia ixx="100" ixy="0" ixz="0" iyy="100" iyz="0" izz="100" />
        </inertial>
        <visual>
            <origin xyz="0 0 -0.49744406562410487" rpy="0 0 0"/>
            <geometry>
                <box size="0.7785397831916696 0.680726027999768 0.9948881312482097" />
            </geometry>
            <material name="Green">
                <color rgba="0 1.0 0 1.0"/>
            </material>
        </visual>
        <collision>
            <origin xyz="0 0 -0.49744406562410487" rpy="0 0 0"/>
            <geometry>
                <box size="0.7785397831916696 0.680726027999768 0.9948881312482097" />
            </geometry>
        </collision>
    </link>
    <link name="Link2">
        <inertial>
            <origin xyz="-0.39654848877607113 0 0" rpy="0 0 0"/>
            <mass value="1" />
            <inertia ixx="100" ixy="0" ixz="0" iyy="100" iyz="0" izz="100" />
        </inertial>
        <visual>
            <origin xyz="-0.39654848877607113 0 0" rpy="0 0 0"/>
            <geometry>
                <box size="0.7930969775521423 0.5934650335750494 0.9982544497916869" />
            </geometry>
            <material name="Cyan">
                <color rgba="0 1.0 1.0 1.0"/>
            </material>
        </visual>
        <collision>
            <origin xyz="-0.39654848877607113 0 0" rpy="0 0 0"/>
            <geometry>
                <box size="0.7930969775521423 0.5934650335750494 0.9982544497916869" />
            </geometry>
        </collision>
    </link>
    <link name="Link3">
        <inertial>
            <origin xyz="-0.14818076868281188 0 0" rpy="0 0 0"/>
            <mass value="1" />
            <inertia ixx="100" ixy="0" ixz="0" iyy="100" iyz="0" izz="100" />
        </inertial>
        <visual>
            <origin xyz="-0.14818076868281188 0 0" rpy="0 0 0"/>
            <geometry>
                <box size="0.29636153736562376 0.8823558091143864 0.8375191234156102" />
            </geometry>
            <material name="Green">
                <color rgba="0 1.0 0 1.0"/>
            </material>
        </visual>
        <collision>
            <origin xyz="-0.14818076868281188 0 0" rpy="0 0 0"/>
            <geometry>
                <box size="0.29636153736562376 0.8823558091143864 0.8375191234156102" />
            </geometry>
        </collision>
    </link>
    <link name="Link4">
        <inertial>
            <origin xyz="0.18138709647275036 0 0" rpy="0 0 0"/>
            <mass value="1" />
            <inertia ixx="100" ixy="0" ixz="0" iyy="100" iyz="0" izz="100" />
        </inertial>
        <visual>
            <origin xyz="0.18138709647275036 0 0" rpy="0 0 0"/>
            <geometry>
                <box size="0.36277419294550073 0.5284822607319241 0.9541392134941872" />
            </geometry>
            <material name="Green">
                <color rgba="0 1.0 0 1.0"/>
            </material>
        </visual>
        <collision>
            <origin xyz="0.18138709647275036 0 0" rpy="0 0 0"/>
            <geometry>
                <box size="0.36277419294550073 0.5284822607319241 0.9541392134941872" />
            </geometry>
        </collision>
    </link>
    <link name="Link5">
        <inertial>
            <origin xyz="0 -0.08667547100924106 0" rpy="0 0 0"/>
            <mass value="1" />
            <inertia ixx="100" ixy="0" ixz="0" iyy="100" iyz="0" izz="100" />
        </inertial>
        <visual>
            <origin xyz="0 -0.08667547100924106 0" rpy="0 0 0"/>
            <geometry>
                <box size="0.29429265150177397 0.1733509420184821 0.09863964296075456" />
            </geometry>
            <material name="Cyan">
                <color rgba="0 1.0 1.0 1.0"/>
            </material>
        </visual>
        <collision>
            <origin xyz="0 -0.08667547100924106 0" rpy="0 0 0"/>
            <geometry>
                <box size="0.29429265150177397 0.1733509420184821 0.09863964296075456" />
            </geometry>
        </collision>
    </link>
    <joint name="Link0_Link4" type="revolute">
       <parent link="Link0"/>
       <child  link="Link4"/>
       <origin rpy="0 0 0" xyz="0.43515894217808126 -0.29525557160923976 2.1645437270168237" />
     <axis xyz="0 0 1"/>
       <limit effort="0.0" lower="-3.14159" upper="3.14159" velocity="0.0"/>
    </joint>
    <joint name="Link0_Link2" type="revolute">
       <parent link="Link0"/>
       <child  link="Link2"/>
       <origin rpy="0 0 0" xyz="-0.43515894217808126 -0.195634282894127 2.38550558601305" />
     <axis xyz="1 0 0"/>
       <limit effort="0.0" lower="-3.14159" upper="3.14159" velocity="0.0"/>
    </joint>
    <joint name="Link0_Link1" type="revolute">
       <parent link="Link0"/>
       <child  link="Link1"/>
       <origin rpy="0 0 0" xyz="0.2986458680899771 -0.28443168819152437 1.552719525448965" />
     <axis xyz="0 1 0"/>
       <limit effort="0.0" lower="-3.14159" upper="3.14159" velocity="0.0"/>
    </joint>
    <joint name="Link1_Link5" type="revolute">
       <parent link="Link1"/>
       <child  link="Link5"/>
       <origin rpy="0 0 0" xyz="0.3871293987276989 -0.340363013999884 -0.1043051076568004" />
     <axis xyz="0 1 0"/>
       <limit effort="0.0" lower="-3.14159" upper="3.14159" velocity="0.0"/>
    </joint>
    <joint name="Link2_Link3" type="revolute">
       <parent link="Link2"/>
       <child  link="Link3"/>
       <origin rpy="0 0 0" xyz="-0.7930969775521423 0.276123034485291 0.4085194276132982" />
     <axis xyz="0 1 0"/>
       <limit effort="0.0" lower="-3.14159" upper="3.14159" velocity="0.0"/>
    </joint>
</robot>