<robot name = "robot">
    <link name="Link0">
        <inertial>
            <origin xyz="0 0 2.25" rpy="0 0 0"/>
            <mass value="1" />
            <inertia ixx="100" ixy="0" ixz="0" iyy="100" iyz="0" izz="100" />
        </inertial>
        <visual>
            <origin xyz="0 0 2.25" rpy="0 0 0"/>
            <geometry>
                <box size="0.8096885313573704 0.8884966225516906 0.8055692729483329" />
            </geometry>
            <material name="Green">
                <color rgba="0 1.0 0 1.0"/>
            </material>
        </visual>
        <collision>
            <origin xyz="0 0 2.25" rpy="0 0 0"/>
            <geometry>
                <box size="0.8096885313573704 0.8884966225516906 0.8055692729483329" />
            </geometry>
        </collision>
    </link>
    <link name="Link1">
        <inertial>
            <origin xyz="0 0.37683719355308565 0" rpy="0 0 0"/>
            <mass value="1" />
            <inertia ixx="100" ixy="0" ixz="0" iyy="100" iyz="0" izz="100" />
        </inertial>
        <visual>
            <origin xyz="0 0.37683719355308565 0" rpy="0 0 0"/>
            <geometry>
                <box size="0.5053257979994896 0.7536743871061713 0.9863512711853385" />
            </geometry>
            <material name="Cyan">
                <color rgba="0 1.0 1.0 1.0"/>
            </material>
        </visual>
        <collision>
            <origin xyz="0 0.37683719355308565 0" rpy="0 0 0"/>
            <geometry>
                <box size="0.5053257979994896 0.7536743871061713 0.9863512711853385" />
            </geometry>
        </collision>
    </link>
    <link name="Link2">
        <inertial>
            <origin xyz="0 0 -0.2443333720600489" rpy="0 0 0"/>
            <mass value="1" />
            <inertia ixx="100" ixy="0" ixz="0" iyy="100" iyz="0" izz="100" />
        </inertial>
        <visual>
            <origin xyz="0 0 -0.2443333720600489" rpy="0 0 0"/>
            <geometry>
                <box size="0.36929195216782573 0.6622695575174423 0.4886667441200978" />
            </geometry>
            <material name="Cyan">
                <color rgba="0 1.0 1.0 1.0"/>
            </material>
        </visual>
        <collision>
            <origin xyz="0 0 -0.2443333720600489" rpy="0 0 0"/>
            <geometry>
                <box size="0.36929195216782573 0.6622695575174423 0.4886667441200978" />
            </geometry>
        </collision>
    </link>
    <link name="Link3">
        <inertial>
            <origin xyz="-0.45447389651061937 0 0" rpy="0 0 0"/>
            <mass value="1" />
            <inertia ixx="100" ixy="0" ixz="0" iyy="100" iyz="0" izz="100" />
        </inertial>
        <visual>
            <origin xyz="-0.45447389651061937 0 0" rpy="0 0 0"/>
            <geometry>
                <box size="0.9089477930212387 0.30125837529142674 0.34224638385452555" />
            </geometry>
            <material name="Cyan">
                <color rgba="0 1.0 1.0 1.0"/>
            </material>
        </visual>
        <collision>
            <origin xyz="-0.45447389651061937 0 0" rpy="0 0 0"/>
            <geometry>
                <box size="0.9089477930212387 0.30125837529142674 0.34224638385452555" />
            </geometry>
        </collision>
    </link>
    <link name="Link4">
        <inertial>
            <origin xyz="0 0.05412690835840639 0" rpy="0 0 0"/>
            <mass value="1" />
            <inertia ixx="100" ixy="0" ixz="0" iyy="100" iyz="0" izz="100" />
        </inertial>
        <visual>
            <origin xyz="0 0.05412690835840639 0" rpy="0 0 0"/>
            <geometry>
                <box size="0.7905035787582296 0.10825381671681278 0.9106811136978418" />
            </geometry>
            <material name="Cyan">
                <color rgba="0 1.0 1.0 1.0"/>
            </material>
        </visual>
        <collision>
            <origin xyz="0 0.05412690835840639 0" rpy="0 0 0"/>
            <geometry>
                <box size="0.7905035787582296 0.10825381671681278 0.9106811136978418" />
            </geometry>
        </collision>
    </link>
    <link name="Link5">
        <inertial>
            <origin xyz="0 -0.23726174335922623 0" rpy="0 0 0"/>
            <mass value="1" />
            <inertia ixx="100" ixy="0" ixz="0" iyy="100" iyz="0" izz="100" />
        </inertial>
        <visual>
            <origin xyz="0 -0.23726174335922623 0" rpy="0 0 0"/>
            <geometry>
                <box size="0.052875876178131054 0.47452348671845246 0.3303401500287453" />
            </geometry>
            <material name="Cyan">
                <color rgba="0 1.0 1.0 1.0"/>
            </material>
        </visual>
        <collision>
            <origin xyz="0 -0.23726174335922623 0" rpy="0 0 0"/>
            <geometry>
                <box size="0.052875876178131054 0.47452348671845246 0.3303401500287453" />
            </geometry>
        </collision>
    </link>
    <link name="Link6">
        <inertial>
            <origin xyz="0 0 -0.3034377945935089" rpy="0 0 0"/>
            <mass value="1" />
            <inertia ixx="100" ixy="0" ixz="0" iyy="100" iyz="0" izz="100" />
        </inertial>
        <visual>
            <origin xyz="0 0 -0.3034377945935089" rpy="0 0 0"/>
            <geometry>
                <box size="0.14118838964587743 0.07867247980029901 0.6068755891870178" />
            </geometry>
            <material name="Green">
                <color rgba="0 1.0 0 1.0"/>
            </material>
        </visual>
        <collision>
            <origin xyz="0 0 -0.3034377945935089" rpy="0 0 0"/>
            <geometry>
                <box size="0.14118838964587743 0.07867247980029901 0.6068755891870178" />
            </geometry>
        </collision>
    </link>
    <joint name="Link0_Link3" type="revolute">
       <parent link="Link0"/>
       <child  link="Link3"/>
       <origin rpy="0 0 0" xyz="-0.4048442656786852 -0.4188118950966877 2.330639701155379" />
     <axis xyz="0 0 1"/>
       <limit effort="0.0" lower="-3.14159" upper="3.14159" velocity="0.0"/>
    </joint>
    <joint name="Link0_Link1" type="revolute">
       <parent link="Link0"/>
       <child  link="Link1"/>
       <origin rpy="0 0 0" xyz="-0.3978722830373717 0.4442483112758453 2.0719436542630714" />
     <axis xyz="0 0 1"/>
       <limit effort="0.0" lower="-3.14159" upper="3.14159" velocity="0.0"/>
    </joint>
    <joint name="Link1_Link4" type="revolute">
       <parent link="Link1"/>
       <child  link="Link4"/>
       <origin rpy="0 0 0" xyz="-0.050763582616612034 0.7536743871061713 0.23476341577071919" />
     <axis xyz="0 0 1"/>
       <limit effort="0.0" lower="-3.14159" upper="3.14159" velocity="0.0"/>
    </joint>
    <joint name="Link1_Link2" type="revolute">
       <parent link="Link1"/>
       <child  link="Link2"/>
       <origin rpy="0 0 0" xyz="0.13115045743784165 0.7020745492473057 -0.49317563559266925" />
     <axis xyz="0 0 1"/>
       <limit effort="0.0" lower="-3.14159" upper="3.14159" velocity="0.0"/>
    </joint>
    <joint name="Link2_Link5" type="revolute">
       <parent link="Link2"/>
       <child  link="Link5"/>
       <origin rpy="0 0 0" xyz="-0.022340523482710845 -0.3311347787587211 -0.315330091215334" />
     <axis xyz="0 0 1"/>
       <limit effort="0.0" lower="-3.14159" upper="3.14159" velocity="0.0"/>
    </joint>
    <joint name="Link5_Link6" type="revolute">
       <parent link="Link5"/>
       <child  link="Link6"/>
       <origin rpy="0 0 0" xyz="0.01517692208299903 -0.17015193186193758 -0.16517007501437264" />
     <axis xyz="0 1 0"/>
       <limit effort="0.0" lower="-3.14159" upper="3.14159" velocity="0.0"/>
    </joint>
</robot>