<robot name = "robot">
    <link name="Link0">
        <inertial>
            <origin xyz="0 0 1.75" rpy="0 0 0"/>
            <mass value="1" />
            <inertia ixx="100" ixy="0" ixz="0" iyy="100" iyz="0" izz="100" />
        </inertial>
        <visual>
            <origin xyz="0 0 1.75" rpy="0 0 0"/>
            <geometry>
                <box size="0.9957117449618709 0.22230873723277955 0.9658285680562738" />
            </geometry>
            <material name="Green">
                <color rgba="0 1.0 0 1.0"/>
            </material>
        </visual>
        <collision>
            <origin xyz="0 0 1.75" rpy="0 0 0"/>
            <geometry>
                <box size="0.9957117449618709 0.22230873723277955 0.9658285680562738" />
            </geometry>
        </collision>
    </link>
    <link name="Link1">
        <inertial>
            <origin xyz="-0.4557328200887459 0 0" rpy="0 0 0"/>
            <mass value="1" />
            <inertia ixx="100" ixy="0" ixz="0" iyy="100" iyz="0" izz="100" />
        </inertial>
        <visual>
            <origin xyz="-0.4557328200887459 0 0" rpy="0 0 0"/>
            <geometry>
                <box size="0.9114656401774918 0.20011334835850414 0.9528286178022988" />
            </geometry>
            <material name="Cyan">
                <color rgba="0 1.0 1.0 1.0"/>
            </material>
        </visual>
        <collision>
            <origin xyz="-0.4557328200887459 0 0" rpy="0 0 0"/>
            <geometry>
                <box size="0.9114656401774918 0.20011334835850414 0.9528286178022988" />
            </geometry>
        </collision>
    </link>
    <link name="Link2">
        <inertial>
            <origin xyz="0 0.4618505417781611 0" rpy="0 0 0"/>
            <mass value="1" />
            <inertia ixx="100" ixy="0" ixz="0" iyy="100" iyz="0" izz="100" />
        </inertial>
        <visual>
            <origin xyz="0 0.4618505417781611 0" rpy="0 0 0"/>
            <geometry>
                <box size="0.12272457671040349 0.9237010835563222 0.6582350537424156" />
            </geometry>
            <material name="Cyan">
                <color rgba="0 1.0 1.0 1.0"/>
            </material>
        </visual>
        <collision>
            <origin xyz="0 0.4618505417781611 0" rpy="0 0 0"/>
            <geometry>
                <box size="0.12272457671040349 0.9237010835563222 0.6582350537424156" />
            </geometry>
        </collision>
    </link>
    <link name="Link3">
        <inertial>
            <origin xyz="0 0 -0.17925062293310895" rpy="0 0 0"/>
            <mass value="1" />
            <inertia ixx="100" ixy="0" ixz="0" iyy="100" iyz="0" izz="100" />
        </inertial>
        <visual>
            <origin xyz="0 0 -0.17925062293310895" rpy="0 0 0"/>
            <geometry>
                <box size="0.24521889848176803 0.677920742937533 0.3585012458662179" />
            </geometry>
            <material name="Green">
                <color rgba="0 1.0 0 1.0"/>
            </material>
        </visual>
        <collision>
            <origin xyz="0 0 -0.17925062293310895" rpy="0 0 0"/>
            <geometry>
                <box size="0.24521889848176803 0.677920742937533 0.3585012458662179" />
            </geometry>
        </collision>
    </link>
    <link name="Link4">
        <inertial>
            <origin xyz="0 -0.1984098835994922 0" rpy="0 0 0"/>
            <mass value="1" />
            <inertia ixx="100" ixy="0" ixz="0" iyy="100" iyz="0" izz="100" />
        </inertial>
        <visual>
            <origin xyz="0 -0.1984098835994922 0" rpy="0 0 0"/>
            <geometry>
                <box size="0.058351192843535626 0.3968197671989844 0.40555459629355617" />
            </geometry>
            <material name="Cyan">
                <color rgba="0 1.0 1.0 1.0"/>
            </material>
        </visual>
        <collision>
            <origin xyz="0 -0.1984098835994922 0" rpy="0 0 0"/>
            <geometry>
                <box size="0.058351192843535626 0.3968197671989844 0.40555459629355617" />
            </geometry>
        </collision>
    </link>
    <joint name="Link0_Link1" type="revolute">
       <parent link="Link0"/>
       <child  link="Link1"/>
       <origin rpy="0 0 0" xyz="-0.49785587248093544 -0.0510692393309732 1.6953989178270485" />
     <axis xyz="0 1 0"/>
       <limit effort="0.0" lower="-3.14159" upper="3.14159" velocity="0.0"/>
    </joint>
    <joint name="Link0_Link2" type="revolute">
       <parent link="Link0"/>
       <child  link="Link2"/>
       <origin rpy="0 0 0" xyz="0.2683362951184341 0.11115436861638978 1.816997592374871" />
     <axis xyz="0 1 0"/>
       <limit effort="0.0" lower="-3.14159" upper="3.14159" velocity="0.0"/>
    </joint>
    <joint name="Link2_Link3" type="revolute">
       <parent link="Link2"/>
       <child  link="Link3"/>
       <origin rpy="0 0 0" xyz="0.03729080516086731 0.02684834738056341 -0.3291175268712078" />
     <axis xyz="1 0 0"/>
       <limit effort="0.0" lower="-3.14159" upper="3.14159" velocity="0.0"/>
    </joint>
    <joint name="Link3_Link4" type="revolute">
       <parent link="Link3"/>
       <child  link="Link4"/>
       <origin rpy="0 0 0" xyz="0.02900465860396584 -0.3389603714687665 -0.3046945165650225" />
     <axis xyz="1 0 0"/>
       <limit effort="0.0" lower="-3.14159" upper="3.14159" velocity="0.0"/>
    </joint>
</robot>