<robot name = "robot">
    <link name="Link0">
        <inertial>
            <origin xyz="0 0 1.25" rpy="0 0 0"/>
            <mass value="1" />
            <inertia ixx="100" ixy="0" ixz="0" iyy="100" iyz="0" izz="100" />
        </inertial>
        <visual>
            <origin xyz="0 0 1.25" rpy="0 0 0"/>
            <geometry>
                <box size="0.9950794409092897 0.9989957744800498 0.7092982239140498" />
            </geometry>
            <material name="Cyan">
                <color rgba="0 1.0 1.0 1.0"/>
            </material>
        </visual>
        <collision>
            <origin xyz="0 0 1.25" rpy="0 0 0"/>
            <geometry>
                <box size="0.9950794409092897 0.9989957744800498 0.7092982239140498" />
            </geometry>
        </collision>
    </link>
    <link name="Link1">
        <inertial>
            <origin xyz="0.43495897365232883 0 0" rpy="0 0 0"/>
            <mass value="1" />
            <inertia ixx="100" ixy="0" ixz="0" iyy="100" iyz="0" izz="100" />
        </inertial>
        <visual>
            <origin xyz="0.43495897365232883 0 0" rpy="0 0 0"/>
            <geometry>
                <box size="0.8699179473046577 0.7478037530152631 0.9834718855892974" />
            </geometry>
            <material name="Green">
                <color rgba="0 1.0 0 1.0"/>
            </material>
        </visual>
        <collision>
            <origin xyz="0.43495897365232883 0 0" rpy="0 0 0"/>
            <geometry>
                <box size="0.8699179473046577 0.7478037530152631 0.9834718855892974" />
            </geometry>
        </collision>
    </link>
    <link name="Link2">
        <inertial>
            <origin xyz="0 0 -0.35827853701858503" rpy="0 0 0"/>
            <mass value="1" />
            <inertia ixx="100" ixy="0" ixz="0" iyy="100" iyz="0" izz="100" />
        </inertial>
        <visual>
            <origin xyz="0 0 -0.35827853701858503" rpy="0 0 0"/>
            <geometry>
                <box size="0.8456908098543681 0.8644788960922724 0.7165570740371701" />
            </geometry>
            <material name="Green">
                <color rgba="0 1.0 0 1.0"/>
            </material>
        </visual>
        <collision>
            <origin xyz="0 0 -0.35827853701858503" rpy="0 0 0"/>
            <geometry>
                <box size="0.8456908098543681 0.8644788960922724 0.7165570740371701" />
            </geometry>
        </collision>
    </link>
    <joint name="Link0_Link1" type="revolute">
       <parent link="Link0"/>
       <child  link="Link1"/>
       <origin rpy="0 0 0" xyz="0.49753972045464484 0.3728324493394977 1.4418357371690143" />
     <axis xyz="0 1 0"/>
       <limit effort="0.0" lower="-3.14159" upper="3.14159" velocity="0.0"/>
    </joint>
    <joint name="Link1_Link2" type="revolute">
       <parent link="Link1"/>
       <child  link="Link2"/>
       <origin rpy="0 0 0" xyz="0.4451357335972081 -0.2931375232072863 -0.4917359427946487" />
     <axis xyz="0 1 0"/>
       <limit effort="0.0" lower="-3.14159" upper="3.14159" velocity="0.0"/>
    </joint>
</robot>