<robot name = "robot">
    <link name="Link0">
        <inertial>
            <origin xyz="0 0 1.5" rpy="0 0 0"/>
            <mass value="1" />
            <inertia ixx="100" ixy="0" ixz="0" iyy="100" iyz="0" izz="100" />
        </inertial>
        <visual>
            <origin xyz="0 0 1.5" rpy="0 0 0"/>
            <geometry>
                <box size="0.7703679216749473 0.8961740313381965 0.2978656218003862" />
            </geometry>
            <material name="Cyan">
                <color rgba="0 1.0 1.0 1.0"/>
            </material>
        </visual>
        <collision>
            <origin xyz="0 0 1.5" rpy="0 0 0"/>
            <geometry>
                <box size="0.7703679216749473 0.8961740313381965 0.2978656218003862" />
            </geometry>
        </collision>
    </link>
    <link name="Link1">
        <inertial>
            <origin xyz="0 0 -0.415545994116124" rpy="0 0 0"/>
            <mass value="1" />
            <inertia ixx="100" ixy="0" ixz="0" iyy="100" iyz="0" izz="100" />
        </inertial>
        <visual>
            <origin xyz="0 0 -0.415545994116124" rpy="0 0 0"/>
            <geometry>
                <box size="0.5502260599328317 0.4299065636727184 0.831091988232248" />
            </geometry>
            <material name="Green">
                <color rgba="0 1.0 0 1.0"/>
            </material>
        </visual>
        <collision>
            <origin xyz="0 0 -0.415545994116124" rpy="0 0 0"/>
            <geometry>
                <box size="0.5502260599328317 0.4299065636727184 0.831091988232248" />
            </geometry>
        </collision>
    </link>
    <link name="Link2">
        <inertial>
            <origin xyz="-0.4375256607649564 0 0" rpy="0 0 0"/>
            <mass value="1" />
            <inertia ixx="100" ixy="0" ixz="0" iyy="100" iyz="0" izz="100" />
        </inertial>
        <visual>
            <origin xyz="-0.4375256607649564 0 0" rpy="0 0 0"/>
            <geometry>
                <box size="0.8750513215299128 0.7379107913626873 0.25703989224282864" />
            </geometry>
            <material name="Cyan">
                <color rgba="0 1.0 1.0 1.0"/>
            </material>
        </visual>
        <collision>
            <origin xyz="-0.4375256607649564 0 0" rpy="0 0 0"/>
            <geometry>
                <box size="0.8750513215299128 0.7379107913626873 0.25703989224282864" />
            </geometry>
        </collision>
    </link>
    <link name="Link3">
        <inertial>
            <origin xyz="0 0.09414093484259256 0" rpy="0 0 0"/>
            <mass value="1" />
            <inertia ixx="100" ixy="0" ixz="0" iyy="100" iyz="0" izz="100" />
        </inertial>
        <visual>
            <origin xyz="0 0.09414093484259256 0" rpy="0 0 0"/>
            <geometry>
                <box size="0.5602208950360538 0.18828186968518512 0.07345943597607674" />
            </geometry>
            <material name="Cyan">
                <color rgba="0 1.0 1.0 1.0"/>
            </material>
        </visual>
        <collision>
            <origin xyz="0 0.09414093484259256 0" rpy="0 0 0"/>
            <geometry>
                <box size="0.5602208950360538 0.18828186968518512 0.07345943597607674" />
            </geometry>
        </collision>
    </link>
    <joint name="Link0_Link2" type="revolute">
       <parent link="Link0"/>
       <child  link="Link2"/>
       <origin rpy="0 0 0" xyz="-0.38518396083747364 -0.17166779652792125 1.3990213135395075" />
     <axis xyz="0 1 0"/>
       <limit effort="0.0" lower="-3.14159" upper="3.14159" velocity="0.0"/>
    </joint>
    <joint name="Link0_Link1" type="revolute">
       <parent link="Link0"/>
       <child  link="Link1"/>
       <origin rpy="0 0 0" xyz="0.09053426430921269 0.18963328825808473 1.351067189099807" />
     <axis xyz="0 1 0"/>
       <limit effort="0.0" lower="-3.14159" upper="3.14159" velocity="0.0"/>
    </joint>
    <joint name="Link2_Link3" type="revolute">
       <parent link="Link2"/>
       <child  link="Link3"/>
       <origin rpy="0 0 0" xyz="-0.14118612282789622 0.3689553956813437 -0.11897726960872043" />
     <axis xyz="0 1 0"/>
       <limit effort="0.0" lower="-3.14159" upper="3.14159" velocity="0.0"/>
    </joint>
</robot>