<robot name = "robot">
    <link name="Link0">
        <inertial>
            <origin xyz="0 0 3.75" rpy="0 0 0"/>
            <mass value="1" />
            <inertia ixx="100" ixy="0" ixz="0" iyy="100" iyz="0" izz="100" />
        </inertial>
        <visual>
            <origin xyz="0 0 3.75" rpy="0 0 0"/>
            <geometry>
                <box size="0.9852112993185295 0.9951028256437862 0.9403356757197457" />
            </geometry>
            <material name="Cyan">
                <color rgba="0 1.0 1.0 1.0"/>
            </material>
        </visual>
        <collision>
            <origin xyz="0 0 3.75" rpy="0 0 0"/>
            <geometry>
                <box size="0.9852112993185295 0.9951028256437862 0.9403356757197457" />
            </geometry>
        </collision>
    </link>
    <joint name="Link0_Link2" type="revolute">
       <parent link="Link0"/>
       <child  link="Link2"/>
       <origin rpy="0 0 0" xyz="-0.49260564965926473 0.08285265534124264 3.7024543519120567" />
     <axis xyz="0 1 0"/>
       <limit effort="0.0" lower="-3.14159" upper="3.14159" velocity="0.0"/>
    </joint>
    <joint name="Link0_Link1" type="revolute">
       <parent link="Link0"/>
       <child  link="Link1"/>
       <origin rpy="0 0 0" xyz="0.3090733900756815 -0.37396295014700914 4.220167837859873" />
     <axis xyz="1 0 0"/>
       <limit effort="0.0" lower="-3.14159" upper="3.14159" velocity="0.0"/>
    </joint>
    <joint name="Link0_Link3" type="revolute">
       <parent link="Link0"/>
       <child  link="Link3"/>
       <origin rpy="0 0 0" xyz="0.3433986714832485 -0.07752539242063615 3.279832162140127" />
     <axis xyz="0 0 1"/>
       <limit effort="0.0" lower="-3.14159" upper="3.14159" velocity="0.0"/>
    </joint>
    <link name="Link1">
        <inertial>
            <origin xyz="0 0 0.16220399994261275" rpy="0 0 0"/>
            <mass value="1" />
            <inertia ixx="100" ixy="0" ixz="0" iyy="100" iyz="0" izz="100" />
        </inertial>
        <visual>
            <origin xyz="0 0 0.16220399994261275" rpy="0 0 0"/>
            <geometry>
                <box size="0.33308592340412857 0.4427871924614436 0.3244079998852255" />
            </geometry>
            <material name="Cyan">
                <color rgba="0 1.0 1.0 1.0"/>
            </material>
        </visual>
        <collision>
            <origin xyz="0 0 0.16220399994261275" rpy="0 0 0"/>
            <geometry>
                <box size="0.33308592340412857 0.4427871924614436 0.3244079998852255" />
            </geometry>
        </collision>
    </link>
    <link name="Link2">
        <inertial>
            <origin xyz="-0.17424100135199216 0 0" rpy="0 0 0"/>
            <mass value="1" />
            <inertia ixx="100" ixy="0" ixz="0" iyy="100" iyz="0" izz="100" />
        </inertial>
        <visual>
            <origin xyz="-0.17424100135199216 0 0" rpy="0 0 0"/>
            <geometry>
                <box size="0.34848200270398433 0.039067578426839944 0.8277133867706974" />
            </geometry>
            <material name="Cyan">
                <color rgba="0 1.0 1.0 1.0"/>
            </material>
        </visual>
        <collision>
            <origin xyz="-0.17424100135199216 0 0" rpy="0 0 0"/>
            <geometry>
                <box size="0.34848200270398433 0.039067578426839944 0.8277133867706974" />
            </geometry>
        </collision>
    </link>
    <link name="Link3">
        <inertial>
            <origin xyz="0 0 -0.019495886128648166" rpy="0 0 0"/>
            <mass value="1" />
            <inertia ixx="100" ixy="0" ixz="0" iyy="100" iyz="0" izz="100" />
        </inertial>
        <visual>
            <origin xyz="0 0 -0.019495886128648166" rpy="0 0 0"/>
            <geometry>
                <box size="0.8796009860400128 0.0712771072931756 0.03899177225729633" />
            </geometry>
            <material name="Cyan">
                <color rgba="0 1.0 1.0 1.0"/>
            </material>
        </visual>
        <collision>
            <origin xyz="0 0 -0.019495886128648166" rpy="0 0 0"/>
            <geometry>
                <box size="0.8796009860400128 0.0712771072931756 0.03899177225729633" />
            </geometry>
        </collision>
    </link>
    <joint name="Link3_Link4" type="revolute">
       <parent link="Link3"/>
       <child  link="Link4"/>
       <origin rpy="0 0 0" xyz="0.4398004930200064 0.015015304399711714 -0.005105622372006607" />
     <axis xyz="0 1 0"/>
       <limit effort="0.0" lower="-3.14159" upper="3.14159" velocity="0.0"/>
    </joint>
    <link name="Link4">
        <inertial>
            <origin xyz="0.36268335083558834 0 0" rpy="0 0 0"/>
            <mass value="1" />
            <inertia ixx="100" ixy="0" ixz="0" iyy="100" iyz="0" izz="100" />
        </inertial>
        <visual>
            <origin xyz="0.36268335083558834 0 0" rpy="0 0 0"/>
            <geometry>
                <box size="0.7253667016711767 0.38023609644590306 0.008469915826234464" />
            </geometry>
            <material name="Green">
                <color rgba="0 1.0 0 1.0"/>
            </material>
        </visual>
        <collision>
            <origin xyz="0.36268335083558834 0 0" rpy="0 0 0"/>
            <geometry>
                <box size="0.7253667016711767 0.38023609644590306 0.008469915826234464" />
            </geometry>
        </collision>
    </link>
</robot>