<robot name = "robot">
    <link name="Link0">
        <inertial>
            <origin xyz="0 0 2.25" rpy="0 0 0"/>
            <mass value="1" />
            <inertia ixx="100" ixy="0" ixz="0" iyy="100" iyz="0" izz="100" />
        </inertial>
        <visual>
            <origin xyz="0 0 2.25" rpy="0 0 0"/>
            <geometry>
                <box size="0.7381377183815432 0.5412165421259009 0.980067518008785" />
            </geometry>
            <material name="Green">
                <color rgba="0 1.0 0 1.0"/>
            </material>
        </visual>
        <collision>
            <origin xyz="0 0 2.25" rpy="0 0 0"/>
            <geometry>
                <box size="0.7381377183815432 0.5412165421259009 0.980067518008785" />
            </geometry>
        </collision>
    </link>
    <joint name="Link0_Link1" type="revolute">
       <parent link="Link0"/>
       <child  link="Link1"/>
       <origin rpy="0 0 0" xyz="-0.24886201402362687 0.017689445069951796 1.7599662409956074" />
     <axis xyz="0 1 0"/>
       <limit effort="0.0" lower="-3.14159" upper="3.14159" velocity="0.0"/>
    </joint>
    <link name="Link1">
        <inertial>
            <origin xyz="0 0 -0.06505276327324527" rpy="0 0 0"/>
            <mass value="1" />
            <inertia ixx="100" ixy="0" ixz="0" iyy="100" iyz="0" izz="100" />
        </inertial>
        <visual>
            <origin xyz="0 0 -0.06505276327324527" rpy="0 0 0"/>
            <geometry>
                <box size="0.7036680490464807 0.08581562571658852 0.13010552654649055" />
            </geometry>
            <material name="Green">
                <color rgba="0 1.0 0 1.0"/>
            </material>
        </visual>
        <collision>
            <origin xyz="0 0 -0.06505276327324527" rpy="0 0 0"/>
            <geometry>
                <box size="0.7036680490464807 0.08581562571658852 0.13010552654649055" />
            </geometry>
        </collision>
    </link>
    <joint name="Link1_Link2" type="revolute">
       <parent link="Link1"/>
       <child  link="Link2"/>
       <origin rpy="0 0 0" xyz="-0.012960898777968506 0.02202227891685851 -0.13010552654649055" />
     <axis xyz="0 0 1"/>
       <limit effort="0.0" lower="-3.14159" upper="3.14159" velocity="0.0"/>
    </joint>
    <link name="Link2">
        <inertial>
            <origin xyz="0 0 -0.18554915093765345" rpy="0 0 0"/>
            <mass value="1" />
            <inertia ixx="100" ixy="0" ixz="0" iyy="100" iyz="0" izz="100" />
        </inertial>
        <visual>
            <origin xyz="0 0 -0.18554915093765345" rpy="0 0 0"/>
            <geometry>
                <box size="0.030028420278136903 0.16562161459188707 0.3710983018753069" />
            </geometry>
            <material name="Green">
                <color rgba="0 1.0 0 1.0"/>
            </material>
        </visual>
        <collision>
            <origin xyz="0 0 -0.18554915093765345" rpy="0 0 0"/>
            <geometry>
                <box size="0.030028420278136903 0.16562161459188707 0.3710983018753069" />
            </geometry>
        </collision>
    </link>
</robot>