<robot name = "robot">
    <link name="Link0">
        <inertial>
            <origin xyz="0 0 1.25" rpy="0 0 0"/>
            <mass value="1" />
            <inertia ixx="100" ixy="0" ixz="0" iyy="100" iyz="0" izz="100" />
        </inertial>
        <visual>
            <origin xyz="0 0 1.25" rpy="0 0 0"/>
            <geometry>
                <box size="0.9957387473917931 0.9737427443957111 0.889743618435696" />
            </geometry>
            <material name="Cyan">
                <color rgba="0 1.0 1.0 1.0"/>
            </material>
        </visual>
        <collision>
            <origin xyz="0 0 1.25" rpy="0 0 0"/>
            <geometry>
                <box size="0.9957387473917931 0.9737427443957111 0.889743618435696" />
            </geometry>
        </collision>
    </link>
    <link name="Link1">
        <inertial>
            <origin xyz="0 0 -0.3115638492849329" rpy="0 0 0"/>
            <mass value="1" />
            <inertia ixx="100" ixy="0" ixz="0" iyy="100" iyz="0" izz="100" />
        </inertial>
        <visual>
            <origin xyz="0 0 -0.3115638492849329" rpy="0 0 0"/>
            <geometry>
                <box size="0.8945648779581786 0.5019396950794932 0.6231276985698658" />
            </geometry>
            <material name="Green">
                <color rgba="0 1.0 0 1.0"/>
            </material>
        </visual>
        <collision>
            <origin xyz="0 0 -0.3115638492849329" rpy="0 0 0"/>
            <geometry>
                <box size="0.8945648779581786 0.5019396950794932 0.6231276985698658" />
            </geometry>
        </collision>
    </link>
    <link name="Link2">
        <inertial>
            <origin xyz="0 -0.24719871155128598 0" rpy="0 0 0"/>
            <mass value="1" />
            <inertia ixx="100" ixy="0" ixz="0" iyy="100" iyz="0" izz="100" />
        </inertial>
        <visual>
            <origin xyz="0 -0.24719871155128598 0" rpy="0 0 0"/>
            <geometry>
                <box size="0.7758431504980423 0.49439742310257195 0.6512838689883177" />
            </geometry>
            <material name="Green">
                <color rgba="0 1.0 0 1.0"/>
            </material>
        </visual>
        <collision>
            <origin xyz="0 -0.24719871155128598 0" rpy="0 0 0"/>
            <geometry>
                <box size="0.7758431504980423 0.49439742310257195 0.6512838689883177" />
            </geometry>
        </collision>
    </link>
    <joint name="Link0_Link2" type="revolute">
       <parent link="Link0"/>
       <child  link="Link2"/>
       <origin rpy="0 0 0" xyz="-0.16955228909241976 -0.48687137219785553 1.262559512697251" />
     <axis xyz="0 1 0"/>
       <limit effort="0.0" lower="-3.14159" upper="3.14159" velocity="0.0"/>
    </joint>
    <joint name="Link0_Link1" type="revolute">
       <parent link="Link0"/>
       <child  link="Link1"/>
       <origin rpy="0 0 0" xyz="-0.28153413180874626 -0.12803310541289536 0.8051281907821519" />
     <axis xyz="1 0 0"/>
       <limit effort="0.0" lower="-3.14159" upper="3.14159" velocity="0.0"/>
    </joint>
</robot>