<robot name = "robot">
    <link name="Link0">
        <inertial>
            <origin xyz="0 0 3.0" rpy="0 0 0"/>
            <mass value="1" />
            <inertia ixx="100" ixy="0" ixz="0" iyy="100" iyz="0" izz="100" />
        </inertial>
        <visual>
            <origin xyz="0 0 3.0" rpy="0 0 0"/>
            <geometry>
                <box size="0.8698459160862931 0.766549782309586 0.5343693857877972" />
            </geometry>
            <material name="Cyan">
                <color rgba="0 1.0 1.0 1.0"/>
            </material>
        </visual>
        <collision>
            <origin xyz="0 0 3.0" rpy="0 0 0"/>
            <geometry>
                <box size="0.8698459160862931 0.766549782309586 0.5343693857877972" />
            </geometry>
        </collision>
    </link>
    <link name="Link1">
        <inertial>
            <origin xyz="-0.3434019506886643 0 0" rpy="0 0 0"/>
            <mass value="1" />
            <inertia ixx="100" ixy="0" ixz="0" iyy="100" iyz="0" izz="100" />
        </inertial>
        <visual>
            <origin xyz="-0.3434019506886643 0 0" rpy="0 0 0"/>
            <geometry>
                <box size="0.6868039013773286 0.970543223834589 0.47554364812698147" />
            </geometry>
            <material name="Cyan">
                <color rgba="0 1.0 1.0 1.0"/>
            </material>
        </visual>
        <collision>
            <origin xyz="-0.3434019506886643 0 0" rpy="0 0 0"/>
            <geometry>
                <box size="0.6868039013773286 0.970543223834589 0.47554364812698147" />
            </geometry>
        </collision>
    </link>
    <link name="Link2">
        <inertial>
            <origin xyz="0 -0.4149046662352303 0" rpy="0 0 0"/>
            <mass value="1" />
            <inertia ixx="100" ixy="0" ixz="0" iyy="100" iyz="0" izz="100" />
        </inertial>
        <visual>
            <origin xyz="0 -0.4149046662352303 0" rpy="0 0 0"/>
            <geometry>
                <box size="0.3503251012878923 0.8298093324704606 0.6443862281921271" />
            </geometry>
            <material name="Green">
                <color rgba="0 1.0 0 1.0"/>
            </material>
        </visual>
        <collision>
            <origin xyz="0 -0.4149046662352303 0" rpy="0 0 0"/>
            <geometry>
                <box size="0.3503251012878923 0.8298093324704606 0.6443862281921271" />
            </geometry>
        </collision>
    </link>
    <link name="Link3">
        <inertial>
            <origin xyz="0 0 -0.18256968799129947" rpy="0 0 0"/>
            <mass value="1" />
            <inertia ixx="100" ixy="0" ixz="0" iyy="100" iyz="0" izz="100" />
        </inertial>
        <visual>
            <origin xyz="0 0 -0.18256968799129947" rpy="0 0 0"/>
            <geometry>
                <box size="0.38401134194211917 0.624538048104501 0.36513937598259893" />
            </geometry>
            <material name="Green">
                <color rgba="0 1.0 0 1.0"/>
            </material>
        </visual>
        <collision>
            <origin xyz="0 0 -0.18256968799129947" rpy="0 0 0"/>
            <geometry>
                <box size="0.38401134194211917 0.624538048104501 0.36513937598259893" />
            </geometry>
        </collision>
    </link>
    <joint name="Link0_Link1" type="revolute">
       <parent link="Link0"/>
       <child  link="Link1"/>
       <origin rpy="0 0 0" xyz="-0.43492295804314657 0.2500763347705586 3.064549340676221" />
     <axis xyz="1 0 0"/>
       <limit effort="0.0" lower="-3.14159" upper="3.14159" velocity="0.0"/>
    </joint>
    <joint name="Link0_Link2" type="revolute">
       <parent link="Link0"/>
       <child  link="Link2"/>
       <origin rpy="0 0 0" xyz="0.4065913652430919 -0.383274891154793 3.0338017710734757" />
     <axis xyz="0 1 0"/>
       <limit effort="0.0" lower="-3.14159" upper="3.14159" velocity="0.0"/>
    </joint>
    <joint name="Link0_Link3" type="revolute">
       <parent link="Link0"/>
       <child  link="Link3"/>
       <origin rpy="0 0 0" xyz="0.3777920061195489 -0.09774871332032992 2.7328153071061014" />
     <axis xyz="1 0 0"/>
       <limit effort="0.0" lower="-3.14159" upper="3.14159" velocity="0.0"/>
    </joint>
</robot>