<robot name = "robot">
    <link name="Link0">
        <inertial>
            <origin xyz="0 0 3.75" rpy="0 0 0"/>
            <mass value="1" />
            <inertia ixx="100" ixy="0" ixz="0" iyy="100" iyz="0" izz="100" />
        </inertial>
        <visual>
            <origin xyz="0 0 3.75" rpy="0 0 0"/>
            <geometry>
                <box size="0.743675905431432 0.5455728842737569 0.6577660070066136" />
            </geometry>
            <material name="Green">
                <color rgba="0 1.0 0 1.0"/>
            </material>
        </visual>
        <collision>
            <origin xyz="0 0 3.75" rpy="0 0 0"/>
            <geometry>
                <box size="0.743675905431432 0.5455728842737569 0.6577660070066136" />
            </geometry>
        </collision>
    </link>
    <joint name="Link0_Link2" type="revolute">
       <parent link="Link0"/>
       <child  link="Link2"/>
       <origin rpy="0 0 0" xyz="-0.14843723368577644 0.27278644213687847 4.036649459029009" />
     <axis xyz="1 0 0"/>
       <limit effort="0.0" lower="-3.14159" upper="3.14159" velocity="0.0"/>
    </joint>
    <joint name="Link0_Link3" type="revolute">
       <parent link="Link0"/>
       <child  link="Link3"/>
       <origin rpy="0 0 0" xyz="0.21895664138089563 -0.27278644213687847 4.049904625893437" />
     <axis xyz="0 0 1"/>
       <limit effort="0.0" lower="-3.14159" upper="3.14159" velocity="0.0"/>
    </joint>
    <joint name="Link0_Link1" type="revolute">
       <parent link="Link0"/>
       <child  link="Link1"/>
       <origin rpy="0 0 0" xyz="-0.022776783371865124 0.054100593507037255 3.421116996496693" />
     <axis xyz="0 1 0"/>
       <limit effort="0.0" lower="-3.14159" upper="3.14159" velocity="0.0"/>
    </joint>
    <link name="Link1">
        <inertial>
            <origin xyz="0 0 -0.47205973780749216" rpy="0 0 0"/>
            <mass value="1" />
            <inertia ixx="100" ixy="0" ixz="0" iyy="100" iyz="0" izz="100" />
        </inertial>
        <visual>
            <origin xyz="0 0 -0.47205973780749216" rpy="0 0 0"/>
            <geometry>
                <box size="0.2767709668463678 0.8038717610756981 0.9441194756149843" />
            </geometry>
            <material name="Green">
                <color rgba="0 1.0 0 1.0"/>
            </material>
        </visual>
        <collision>
            <origin xyz="0 0 -0.47205973780749216" rpy="0 0 0"/>
            <geometry>
                <box size="0.2767709668463678 0.8038717610756981 0.9441194756149843" />
            </geometry>
        </collision>
    </link>
    <link name="Link2">
        <inertial>
            <origin xyz="0 0.2878689526711978 0" rpy="0 0 0"/>
            <mass value="1" />
            <inertia ixx="100" ixy="0" ixz="0" iyy="100" iyz="0" izz="100" />
        </inertial>
        <visual>
            <origin xyz="0 0.2878689526711978 0" rpy="0 0 0"/>
            <geometry>
                <box size="0.42478067807515685 0.5757379053423956 0.5835809465964342" />
            </geometry>
            <material name="Cyan">
                <color rgba="0 1.0 1.0 1.0"/>
            </material>
        </visual>
        <collision>
            <origin xyz="0 0.2878689526711978 0" rpy="0 0 0"/>
            <geometry>
                <box size="0.42478067807515685 0.5757379053423956 0.5835809465964342" />
            </geometry>
        </collision>
    </link>
    <link name="Link3">
        <inertial>
            <origin xyz="0 -0.364387591805433 0" rpy="0 0 0"/>
            <mass value="1" />
            <inertia ixx="100" ixy="0" ixz="0" iyy="100" iyz="0" izz="100" />
        </inertial>
        <visual>
            <origin xyz="0 -0.364387591805433 0" rpy="0 0 0"/>
            <geometry>
                <box size="0.15791346032467057 0.728775183610866 0.4407494732784163" />
            </geometry>
            <material name="Cyan">
                <color rgba="0 1.0 1.0 1.0"/>
            </material>
        </visual>
        <collision>
            <origin xyz="0 -0.364387591805433 0" rpy="0 0 0"/>
            <geometry>
                <box size="0.15791346032467057 0.728775183610866 0.4407494732784163" />
            </geometry>
        </collision>
    </link>
    <joint name="Link3_Link4" type="revolute">
       <parent link="Link3"/>
       <child  link="Link4"/>
       <origin rpy="0 0 0" xyz="0.07895673016233529 -0.3937267210715447 0.19480980740179538" />
     <axis xyz="0 0 1"/>
       <limit effort="0.0" lower="-3.14159" upper="3.14159" velocity="0.0"/>
    </joint>
    <link name="Link4">
        <inertial>
            <origin xyz="0.06836451425310403 0 0" rpy="0 0 0"/>
            <mass value="1" />
            <inertia ixx="100" ixy="0" ixz="0" iyy="100" iyz="0" izz="100" />
        </inertial>
        <visual>
            <origin xyz="0.06836451425310403 0 0" rpy="0 0 0"/>
            <geometry>
                <box size="0.13672902850620805 0.2512110451254075 0.8953523515655635" />
            </geometry>
            <material name="Green">
                <color rgba="0 1.0 0 1.0"/>
            </material>
        </visual>
        <collision>
            <origin xyz="0.06836451425310403 0 0" rpy="0 0 0"/>
            <geometry>
                <box size="0.13672902850620805 0.2512110451254075 0.8953523515655635" />
            </geometry>
        </collision>
    </link>
</robot>