<robot name = "robot">
    <link name="Link0">
        <inertial>
            <origin xyz="0 0 3.0" rpy="0 0 0"/>
            <mass value="1" />
            <inertia ixx="100" ixy="0" ixz="0" iyy="100" iyz="0" izz="100" />
        </inertial>
        <visual>
            <origin xyz="0 0 3.0" rpy="0 0 0"/>
            <geometry>
                <box size="0.5838106397874472 0.655116803950095 0.47635345249678784" />
            </geometry>
            <material name="Green">
                <color rgba="0 1.0 0 1.0"/>
            </material>
        </visual>
        <collision>
            <origin xyz="0 0 3.0" rpy="0 0 0"/>
            <geometry>
                <box size="0.5838106397874472 0.655116803950095 0.47635345249678784" />
            </geometry>
        </collision>
    </link>
    <joint name="Link0_Link3" type="revolute">
       <parent link="Link0"/>
       <child  link="Link3"/>
       <origin rpy="0 0 0" xyz="0.2919053198937236 0.06187974180615632 2.8027957866431232" />
     <axis xyz="0 1 0"/>
       <limit effort="0.0" lower="-3.14159" upper="3.14159" velocity="0.0"/>
    </joint>
    <joint name="Link0_Link1" type="revolute">
       <parent link="Link0"/>
       <child  link="Link1"/>
       <origin rpy="0 0 0" xyz="0.20735710348389325 -0.25475584241268023 2.761823273751606" />
     <axis xyz="1 0 0"/>
       <limit effort="0.0" lower="-3.14159" upper="3.14159" velocity="0.0"/>
    </joint>
    <link name="Link1">
        <inertial>
            <origin xyz="0 0 -0.2714827780465928" rpy="0 0 0"/>
            <mass value="1" />
            <inertia ixx="100" ixy="0" ixz="0" iyy="100" iyz="0" izz="100" />
        </inertial>
        <visual>
            <origin xyz="0 0 -0.2714827780465928" rpy="0 0 0"/>
            <geometry>
                <box size="0.596977742156994 0.24625608163736235 0.5429655560931856" />
            </geometry>
            <material name="Green">
                <color rgba="0 1.0 0 1.0"/>
            </material>
        </visual>
        <collision>
            <origin xyz="0 0 -0.2714827780465928" rpy="0 0 0"/>
            <geometry>
                <box size="0.596977742156994 0.24625608163736235 0.5429655560931856" />
            </geometry>
        </collision>
    </link>
    <joint name="Link1_Link2" type="revolute">
       <parent link="Link1"/>
       <child  link="Link2"/>
       <origin rpy="0 0 0" xyz="0.14791374954511335 0.12312804081868116 -0.22878476468725267" />
     <axis xyz="0 0 1"/>
       <limit effort="0.0" lower="-3.14159" upper="3.14159" velocity="0.0"/>
    </joint>
    <link name="Link2">
        <inertial>
            <origin xyz="0 0.047017604038718075 0" rpy="0 0 0"/>
            <mass value="1" />
            <inertia ixx="100" ixy="0" ixz="0" iyy="100" iyz="0" izz="100" />
        </inertial>
        <visual>
            <origin xyz="0 0.047017604038718075 0" rpy="0 0 0"/>
            <geometry>
                <box size="0.7162327664475863 0.09403520807743615 0.5211041522268515" />
            </geometry>
            <material name="Cyan">
                <color rgba="0 1.0 1.0 1.0"/>
            </material>
        </visual>
        <collision>
            <origin xyz="0 0.047017604038718075 0" rpy="0 0 0"/>
            <geometry>
                <box size="0.7162327664475863 0.09403520807743615 0.5211041522268515" />
            </geometry>
        </collision>
    </link>
    <link name="Link3">
        <inertial>
            <origin xyz="0.3124722549793516 0 0" rpy="0 0 0"/>
            <mass value="1" />
            <inertia ixx="100" ixy="0" ixz="0" iyy="100" iyz="0" izz="100" />
        </inertial>
        <visual>
            <origin xyz="0.3124722549793516 0 0" rpy="0 0 0"/>
            <geometry>
                <box size="0.6249445099587032 0.01598043454082898 0.47217563366326365" />
            </geometry>
            <material name="Green">
                <color rgba="0 1.0 0 1.0"/>
            </material>
        </visual>
        <collision>
            <origin xyz="0.3124722549793516 0 0" rpy="0 0 0"/>
            <geometry>
                <box size="0.6249445099587032 0.01598043454082898 0.47217563366326365" />
            </geometry>
        </collision>
    </link>
</robot>