<robot name = "robot">
    <link name="Link0">
        <inertial>
            <origin xyz="0 0 3.0" rpy="0 0 0"/>
            <mass value="1" />
            <inertia ixx="100" ixy="0" ixz="0" iyy="100" iyz="0" izz="100" />
        </inertial>
        <visual>
            <origin xyz="0 0 3.0" rpy="0 0 0"/>
            <geometry>
                <box size="0.9845728626740549 0.34932559527241 0.3493836201754975" />
            </geometry>
            <material name="Green">
                <color rgba="0 1.0 0 1.0"/>
            </material>
        </visual>
        <collision>
            <origin xyz="0 0 3.0" rpy="0 0 0"/>
            <geometry>
                <box size="0.9845728626740549 0.34932559527241 0.3493836201754975" />
            </geometry>
        </collision>
    </link>
    <joint name="Link0_Link1" type="revolute">
       <parent link="Link0"/>
       <child  link="Link1"/>
       <origin rpy="0 0 0" xyz="-0.13980888578096487 -0.174662797636205 3.030611628374058" />
     <axis xyz="0 0 1"/>
       <limit effort="0.0" lower="-3.14159" upper="3.14159" velocity="0.0"/>
    </joint>
    <joint name="Link0_Link2" type="revolute">
       <parent link="Link0"/>
       <child  link="Link2"/>
       <origin rpy="0 0 0" xyz="-0.35389162505046684 -0.06300024899796354 2.8253081899122514" />
     <axis xyz="1 0 0"/>
       <limit effort="0.0" lower="-3.14159" upper="3.14159" velocity="0.0"/>
    </joint>
    <link name="Link1">
        <inertial>
            <origin xyz="0 -0.04655926884032646 0" rpy="0 0 0"/>
            <mass value="1" />
            <inertia ixx="100" ixy="0" ixz="0" iyy="100" iyz="0" izz="100" />
        </inertial>
        <visual>
            <origin xyz="0 -0.04655926884032646 0" rpy="0 0 0"/>
            <geometry>
                <box size="0.9585314681533376 0.09311853768065292 0.9608847884598382" />
            </geometry>
            <material name="Green">
                <color rgba="0 1.0 0 1.0"/>
            </material>
        </visual>
        <collision>
            <origin xyz="0 -0.04655926884032646 0" rpy="0 0 0"/>
            <geometry>
                <box size="0.9585314681533376 0.09311853768065292 0.9608847884598382" />
            </geometry>
        </collision>
    </link>
    <joint name="Link1_Link3" type="revolute">
       <parent link="Link1"/>
       <child  link="Link3"/>
       <origin rpy="0 0 0" xyz="0.4792657340766688 -0.03459476849005692 0.0159874375415277" />
     <axis xyz="0 1 0"/>
       <limit effort="0.0" lower="-3.14159" upper="3.14159" velocity="0.0"/>
    </joint>
    <link name="Link2">
        <inertial>
            <origin xyz="0 0 -0.31363808759692624" rpy="0 0 0"/>
            <mass value="1" />
            <inertia ixx="100" ixy="0" ixz="0" iyy="100" iyz="0" izz="100" />
        </inertial>
        <visual>
            <origin xyz="0 0 -0.31363808759692624" rpy="0 0 0"/>
            <geometry>
                <box size="0.9639832919624907 0.11558618385220731 0.6272761751938525" />
            </geometry>
            <material name="Cyan">
                <color rgba="0 1.0 1.0 1.0"/>
            </material>
        </visual>
        <collision>
            <origin xyz="0 0 -0.31363808759692624" rpy="0 0 0"/>
            <geometry>
                <box size="0.9639832919624907 0.11558618385220731 0.6272761751938525" />
            </geometry>
        </collision>
    </link>
    <link name="Link3">
        <inertial>
            <origin xyz="0.3772358506645938 0 0" rpy="0 0 0"/>
            <mass value="1" />
            <inertia ixx="100" ixy="0" ixz="0" iyy="100" iyz="0" izz="100" />
        </inertial>
        <visual>
            <origin xyz="0.3772358506645938 0 0" rpy="0 0 0"/>
            <geometry>
                <box size="0.7544717013291876 0.1979521536329798 0.26561038128188375" />
            </geometry>
            <material name="Green">
                <color rgba="0 1.0 0 1.0"/>
            </material>
        </visual>
        <collision>
            <origin xyz="0.3772358506645938 0 0" rpy="0 0 0"/>
            <geometry>
                <box size="0.7544717013291876 0.1979521536329798 0.26561038128188375" />
            </geometry>
        </collision>
    </link>
</robot>