<robot name = "robot">
    <link name="Link0">
        <inertial>
            <origin xyz="0 0 3.0" rpy="0 0 0"/>
            <mass value="1" />
            <inertia ixx="100" ixy="0" ixz="0" iyy="100" iyz="0" izz="100" />
        </inertial>
        <visual>
            <origin xyz="0 0 3.0" rpy="0 0 0"/>
            <geometry>
                <box size="0.9237617313862113 0.45043610423830127 0.8742034544062646" />
            </geometry>
            <material name="Cyan">
                <color rgba="0 1.0 1.0 1.0"/>
            </material>
        </visual>
        <collision>
            <origin xyz="0 0 3.0" rpy="0 0 0"/>
            <geometry>
                <box size="0.9237617313862113 0.45043610423830127 0.8742034544062646" />
            </geometry>
        </collision>
    </link>
    <joint name="Link0_Link1" type="revolute">
       <parent link="Link0"/>
       <child  link="Link1"/>
       <origin rpy="0 0 0" xyz="0.37747127221711807 0.22521805211915064 2.8039219425654416" />
     <axis xyz="1 0 0"/>
       <limit effort="0.0" lower="-3.14159" upper="3.14159" velocity="0.0"/>
    </joint>
    <joint name="Link0_Link3" type="revolute">
       <parent link="Link0"/>
       <child  link="Link3"/>
       <origin rpy="0 0 0" xyz="-0.4077940342020335 -0.030465949029943335 2.562898272796868" />
     <axis xyz="1 0 0"/>
       <limit effort="0.0" lower="-3.14159" upper="3.14159" velocity="0.0"/>
    </joint>
    <link name="Link1">
        <inertial>
            <origin xyz="0 0.47680340540800814 0" rpy="0 0 0"/>
            <mass value="1" />
            <inertia ixx="100" ixy="0" ixz="0" iyy="100" iyz="0" izz="100" />
        </inertial>
        <visual>
            <origin xyz="0 0.47680340540800814 0" rpy="0 0 0"/>
            <geometry>
                <box size="0.6903189676260266 0.9536068108160163 0.34595196795319527" />
            </geometry>
            <material name="Green">
                <color rgba="0 1.0 0 1.0"/>
            </material>
        </visual>
        <collision>
            <origin xyz="0 0.47680340540800814 0" rpy="0 0 0"/>
            <geometry>
                <box size="0.6903189676260266 0.9536068108160163 0.34595196795319527" />
            </geometry>
        </collision>
    </link>
    <joint name="Link1_Link2" type="revolute">
       <parent link="Link1"/>
       <child  link="Link2"/>
       <origin rpy="0 0 0" xyz="0.04072206508206577 0.027760813695263065 -0.17297598397659764" />
     <axis xyz="1 0 0"/>
       <limit effort="0.0" lower="-3.14159" upper="3.14159" velocity="0.0"/>
    </joint>
    <link name="Link2">
        <inertial>
            <origin xyz="0 0 -0.2640222083801544" rpy="0 0 0"/>
            <mass value="1" />
            <inertia ixx="100" ixy="0" ixz="0" iyy="100" iyz="0" izz="100" />
        </inertial>
        <visual>
            <origin xyz="0 0 -0.2640222083801544" rpy="0 0 0"/>
            <geometry>
                <box size="0.4995150970701666 0.6699935023162815 0.5280444167603088" />
            </geometry>
            <material name="Cyan">
                <color rgba="0 1.0 1.0 1.0"/>
            </material>
        </visual>
        <collision>
            <origin xyz="0 0 -0.2640222083801544" rpy="0 0 0"/>
            <geometry>
                <box size="0.4995150970701666 0.6699935023162815 0.5280444167603088" />
            </geometry>
        </collision>
    </link>
    <link name="Link3">
        <inertial>
            <origin xyz="0 0 -0.10125842929146506" rpy="0 0 0"/>
            <mass value="1" />
            <inertia ixx="100" ixy="0" ixz="0" iyy="100" iyz="0" izz="100" />
        </inertial>
        <visual>
            <origin xyz="0 0 -0.10125842929146506" rpy="0 0 0"/>
            <geometry>
                <box size="0.08655560833592735 0.8908699168437401 0.20251685858293011" />
            </geometry>
            <material name="Green">
                <color rgba="0 1.0 0 1.0"/>
            </material>
        </visual>
        <collision>
            <origin xyz="0 0 -0.10125842929146506" rpy="0 0 0"/>
            <geometry>
                <box size="0.08655560833592735 0.8908699168437401 0.20251685858293011" />
            </geometry>
        </collision>
    </link>
</robot>