<robot name = "robot">
    <link name="Link0">
        <inertial>
            <origin xyz="0 0 3.75" rpy="0 0 0"/>
            <mass value="1" />
            <inertia ixx="100" ixy="0" ixz="0" iyy="100" iyz="0" izz="100" />
        </inertial>
        <visual>
            <origin xyz="0 0 3.75" rpy="0 0 0"/>
            <geometry>
                <box size="0.9957117449618709 0.22230873723277955 0.9658285680562738" />
            </geometry>
            <material name="Cyan">
                <color rgba="0 1.0 1.0 1.0"/>
            </material>
        </visual>
        <collision>
            <origin xyz="0 0 3.75" rpy="0 0 0"/>
            <geometry>
                <box size="0.9957117449618709 0.22230873723277955 0.9658285680562738" />
            </geometry>
        </collision>
    </link>
    <joint name="Link0_Link2" type="revolute">
       <parent link="Link0"/>
       <child  link="Link2"/>
       <origin rpy="0 0 0" xyz="-0.49785587248093544 0.039380918914249774 4.066008567066185" />
     <axis xyz="0 0 1"/>
       <limit effort="0.0" lower="-3.14159" upper="3.14159" velocity="0.0"/>
    </joint>
    <joint name="Link0_Link4" type="revolute">
       <parent link="Link0"/>
       <child  link="Link4"/>
       <origin rpy="0 0 0" xyz="-0.440633259742262 -0.11115436861638978 3.894186603642089" />
     <axis xyz="0 1 0"/>
       <limit effort="0.0" lower="-3.14159" upper="3.14159" velocity="0.0"/>
    </joint>
    <joint name="Link0_Link1" type="revolute">
       <parent link="Link0"/>
       <child  link="Link1"/>
       <origin rpy="0 0 0" xyz="-0.3544732743839572 -0.09296030027058776 4.232914284028137" />
     <axis xyz="0 0 1"/>
       <limit effort="0.0" lower="-3.14159" upper="3.14159" velocity="0.0"/>
    </joint>
    <link name="Link1">
        <inertial>
            <origin xyz="0 0 0.4333973945279524" rpy="0 0 0"/>
            <mass value="1" />
            <inertia ixx="100" ixy="0" ixz="0" iyy="100" iyz="0" izz="100" />
        </inertial>
        <visual>
            <origin xyz="0 0 0.4333973945279524" rpy="0 0 0"/>
            <geometry>
                <box size="0.11620545532425741 0.9876188801422997 0.8667947890559048" />
            </geometry>
            <material name="Green">
                <color rgba="0 1.0 0 1.0"/>
            </material>
        </visual>
        <collision>
            <origin xyz="0 0 0.4333973945279524" rpy="0 0 0"/>
            <geometry>
                <box size="0.11620545532425741 0.9876188801422997 0.8667947890559048" />
            </geometry>
        </collision>
    </link>
    <link name="Link2">
        <inertial>
            <origin xyz="-0.061362288355201744 0 0" rpy="0 0 0"/>
            <mass value="1" />
            <inertia ixx="100" ixy="0" ixz="0" iyy="100" iyz="0" izz="100" />
        </inertial>
        <visual>
            <origin xyz="-0.061362288355201744 0 0" rpy="0 0 0"/>
            <geometry>
                <box size="0.12272457671040349 0.9237010835563222 0.6582350537424156" />
            </geometry>
            <material name="Cyan">
                <color rgba="0 1.0 1.0 1.0"/>
            </material>
        </visual>
        <collision>
            <origin xyz="-0.061362288355201744 0 0" rpy="0 0 0"/>
            <geometry>
                <box size="0.12272457671040349 0.9237010835563222 0.6582350537424156" />
            </geometry>
        </collision>
    </link>
    <joint name="Link2_Link3" type="revolute">
       <parent link="Link2"/>
       <child  link="Link3"/>
       <origin rpy="0 0 0" xyz="-0.007551611362674501 -0.4618505417781611 -0.011608929180938667" />
     <axis xyz="1 0 0"/>
       <limit effort="0.0" lower="-3.14159" upper="3.14159" velocity="0.0"/>
    </joint>
    <link name="Link3">
        <inertial>
            <origin xyz="0 -0.3389603714687665 0" rpy="0 0 0"/>
            <mass value="1" />
            <inertia ixx="100" ixy="0" ixz="0" iyy="100" iyz="0" izz="100" />
        </inertial>
        <visual>
            <origin xyz="0 -0.3389603714687665 0" rpy="0 0 0"/>
            <geometry>
                <box size="0.24521889848176803 0.677920742937533 0.3585012458662179" />
            </geometry>
            <material name="Cyan">
                <color rgba="0 1.0 1.0 1.0"/>
            </material>
        </visual>
        <collision>
            <origin xyz="0 -0.3389603714687665 0" rpy="0 0 0"/>
            <geometry>
                <box size="0.24521889848176803 0.677920742937533 0.3585012458662179" />
            </geometry>
        </collision>
    </link>
    <link name="Link4">
        <inertial>
            <origin xyz="0 -0.1984098835994922 0" rpy="0 0 0"/>
            <mass value="1" />
            <inertia ixx="100" ixy="0" ixz="0" iyy="100" iyz="0" izz="100" />
        </inertial>
        <visual>
            <origin xyz="0 -0.1984098835994922 0" rpy="0 0 0"/>
            <geometry>
                <box size="0.058351192843535626 0.3968197671989844 0.40555459629355617" />
            </geometry>
            <material name="Cyan">
                <color rgba="0 1.0 1.0 1.0"/>
            </material>
        </visual>
        <collision>
            <origin xyz="0 -0.1984098835994922 0" rpy="0 0 0"/>
            <geometry>
                <box size="0.058351192843535626 0.3968197671989844 0.40555459629355617" />
            </geometry>
        </collision>
    </link>
</robot>